Workbook

Sheet Read_Me
A1: Car and Home Insurance Toolkit (Excel edition)
A2: Version 5.0 (September 29, 2026) · A learning-grade model, not a quote and not advice. Confirm anything you act on with a licensed agent and your state insurance department.
A4: What this workbook is
A5: The data, formulas and checklists behind the web tool, in one place. The two calculators are live: change the blue cells and the estimate, range and percentile recalculate. The quote sheets score themselves once real prices are entered.
A7: Colour legend
A8: Blue text on yellow | B8: Input: edit these
A9: Blue text | B9: Hardcoded data or assumption (change on the data sheets)
A10: Black text | B10: Formula
A11: Green text | B11: Formula that reads another sheet
A13: Sheet guide
A14: Sheet | B14: What it does
A15: Car_Calculator | B15: Live car price check with steps, range, percentile, and your state's legal minimum
A16: Home_Calculator | B16: Live home price check plus rebuild-cost check, storm deductibles, roof exposure and a 12-situation stress test
A17: Car_Data / Home_Data | B17: State tables (51 places plus a national row) and every factor, each marked sourced or assumed
A18: OK_Official_Data | B18: 1,800 real insurer prices from the Oklahoma Insurance Department
A19: OK_Benchmark | B19: Model vs. the median insurer for 11 profiles, plus how much insurers differ (live formulas)
A20: Validation | B20: Before/after and other independent checks
A21: Quote_Requests / Quote_Test | B21: 180 standardized home profiles (TX, FL, CA). Enter real quotes; the sheets score the model
A22: Fairness_Screen / Monitoring | B22: Templates: adverse impact ratios and month-by-month alerts (example rows to replace)
A23: Fairness_Rules_Audit / Controls_Register | B23: What changes the price and the 12-item governance controls with honest status
A24: Min_Liability / Home_Reference | B24: Legal minimums and home insurance facts
A25: Consultancy_Benchmark | B25: What ten consultancies point to and what was built
A26: Checklists / Quote_Kit / Limits_Next_Steps / Sources | B26: How to test, how to collect quotes, what is not done, and where every number came from
A28: The five findings worth knowing
A29: 1. Insurers disagree far more than most people expect: in Oklahoma's official samples the highest insurer charged about 4.7 to 4.9 times the lowest for the same customer.
A30: 2. The first version of the model was 12% to 51% low against those official prices; testing found it and it was corrected.
A31: 3. The biggest home risks are gaps, not price: rebuild cost estimates run from $162 to $350 a square foot, storm deductibles can be thousands of dollars, and an older roof paid at depreciated value can leave most of a replacement to the owner.
A32: 4. When prices rise, many households cut coverage or let policies lapse instead of shopping. Use the ranked ways to save and the "do not cut" reminders in the web tool.
A33: 5. Regulators expect documented, tested and monitored models. The Controls_Register lists what is built and the two controls that are not.
A35: Not done
A36: No real quotes tested in Texas, Florida or California; Oklahoma's samples are partly in-sample.
A37: Home prices are the roughest number.
A38: The address lookup (in the web tool) has passed offline tests only.
A39: Tested in Chromium only (no Safari, Firefox, real-phone or screen-reader test); no legal review.

Sheet Car_Calculator
A1: Car insurance price check (live calculator)
A2: Change the blue cells. The estimate, range and percentile update. A learning model, not a quote.
A4: Your details (edit the blue cells) | E4: Results
A5: State (two-letter code) | B5: TX | C5: dropdown list of codes | E5: Estimate ($ per year, rounded) | F5: =ROUND($B$42,-1) -> 3970
A6: Your age (16 to 99) | B6: 34 | E6: Typical range: low ($) | F6: =ROUND($B$42*EXP(-Car_Data!$B$123*Car_Data!$B$122),-1) -> 2950
A7: Years driving | B7: 16 | E7: Typical range: high ($) | F7: =ROUND($B$42*EXP(Car_Data!$B$123*Car_Data!$B$122),-1) -> 5340
A8: Accidents you caused, past 5 years (0 to 3) | B8: 0 | E8: Your price ($) | F8: =$B$21 -> 2280
A9: Tickets, past 3 years (0 to 3) | B9: 0 | E9: Verdict | F9: =IF(F8>F7,"May be overpaying",IF(F8<F6,"Below typical","Inside the typical range")) -> Below typical
A10: DUI in the past 5 years? | B10: No | C10: Yes or No | E10: Share of expected insurer prices below yours | F10: =IF(AND($B$21>0,$B$42>0),NORMSDIST(LN($B$21/$B$42)/Car_Data!$B$122),0.5) -> 0.10388009
A11: Credit rating (blank to skip) | B11: good | C11: poor, fair, good, excellent | E11: Best-case yearly saving ($) | F11: =MAX(0,F8-F6) -> 0
A12: What the car is worth ($) | B12: 31000 | E12: Published median, reference driver in your state ($) | F12: =$B$26 -> 3608
A13: Cover on your own car | B13: full | C13: full, coll, liab | E13: Legal minimum liability in your state | F13: =INDEX(Car_Data!$J$5:$J$56,$B$25) -> 30/60/25
A14: Deductible ($) | B14: 1000 | C14: 500, 1000 or 2000 | E14: Status of that minimum | F14: =INDEX(Car_Data!$K$5:$K$56,$B$25) -> Checked against an official state source
A15: Liability limits | B15: l100 | C15: min, l50, l100, unsure | E15: Uninsured-motorist rule | F15: =INDEX(Car_Data!$I$5:$I$56,$B$25) -> Must be offered; may be rejected in writing
A16: Miles per year | B16: mid | C16: low, mid, high | E16: No-fault state? (PIP and lawsuit threshold) | F16: =INDEX(Car_Data!$G$5:$G$56,$B$25)&IF(INDEX(Car_Data!$G$5:$G$56,$B$25)="Yes"," - "&INDEX(Car_Data!$H$5:$H$56,$B$25),"") -> No
A17: Use | B17: personal | C17: personal, business, commercial
A18: Flooding where you park? | B18: No | C18: Yes or No | E18: How to read this
A19: Hailstorms where you park? | B19: Yes | C19: Yes or No | E19: The range is the middle half of expected insurer prices. For the same customer, insurers differed by about 4.7x to 4.9x between the highest and lowest in Oklahoma's official samples.
A20: Car thefts where you park? | B20: No | C20: Yes or No | E20: The percentile applies that Oklahoma spread to every state, so treat it as a rough guide.
A21: What you pay per year ($) | B21: 2280 | C21: monthly price x 12 | E21: Credit is ignored where a state bans it. Gender, marital status, occupation, income and ZIP code are not used.
E22: A price below the range can mean thinner coverage. Check limits and deductibles before switching.
A24: Workings (formulas)
A25: State row | B25: =MATCH($B$5,Car_Data!$B$5:$B$56,0) -> 43
A26: Published state median ($) | B26: =INDEX(Car_Data!$C$5:$C$56,$B$25) -> 3608
A27: Liability share | B27: =INDEX(Car_Data!$B$100:$B$103,MATCH($B$15,Car_Data!$A$100:$A$103,0)) -> 0.36
A28: Own-car cover share | B28: =INDEX(Car_Data!$B$104:$B$106,MATCH($B$13,Car_Data!$A$104:$A$106,0)) -> 0.64
A29: Vehicle value factor | B29: =IF($B$28=0,1,MIN(Car_Data!$B$121,MAX(Car_Data!$B$120,(MAX($B$12,1000)/Car_Data!$B$118)^Car_Data!$B$119))) -> 1.0898549
A30: Deductible factor | B30: =IF($B$28=0,1,IF($B$14<=500,Car_Data!$B$113,IF($B$14>=2000,Car_Data!$B$114,1))) -> 1
A31: Area factor (full cover only) | B31: =IF($B$13="full",1+IF(($B$18="Yes"),Car_Data!$B$115,0)+IF(($B$19="Yes"),Car_Data!$B$116,0)+IF(($B$20="Yes"),Car_Data!$B$117,0),1) -> 1.03
A32: Cover factor (liability + own-car) | B32: =$B$27+$B$28*$B$29*$B$30*$B$31 -> 1.0784323
A33: Age table position | B33: =IFERROR(MATCH($B$6,Car_Data!$A$61:$A$74,1),1) -> 5
A34: Age multiple | B34: =IF($B$33>=ROWS(Car_Data!$A$61:$A$74),INDEX(Car_Data!$B$61:$B$74,ROWS(Car_Data!$A$61:$A$74)),INDEX(Car_Data!$B$61:$B$74,$B$33)+(INDEX(Car_Data!$B$61:$B$74,$B$33+1)-INDEX(Car_Data!$B$61:$B$74,$B$33))*($B$6-INDEX(Car_Data!$A$61:$A$74,$B$33))/(INDEX(Car_Data!$A$61:$A$74,$B$33+1)-INDEX(Car_Data!$A$61:$A$74,$B$33))) -> 1.02
A35: Inexperience multiple | B35: =IF($B$7<2,Car_Data!$B$95,1) -> 1
A36: Accident multiple | B36: =INDEX(Car_Data!$B$79:$B$82,MIN(3,MAX(0,$B$8))+1) -> 1
A37: Ticket multiple | B37: =INDEX(Car_Data!$B$83:$B$86,MIN(3,MAX(0,$B$9))+1) -> 1
A38: DUI multiple | B38: =IF(($B$10="Yes"),Car_Data!$B$87,1) -> 1
A39: Mileage multiple | B39: =IF($B$16="high",Car_Data!$B$92,1) -> 1
A40: Use multiple | B40: =IF($B$17="commercial",Car_Data!$B$94,IF($B$17="business",Car_Data!$B$93,1)) -> 1
A41: Credit multiple (1.00 where banned) | B41: =IF(INDEX(Car_Data!$E$5:$E$56,$B$25)="Yes",1,IF($B$11="poor",Car_Data!$B$88,IF($B$11="fair",Car_Data!$B$89,IF($B$11="excellent",Car_Data!$B$91,Car_Data!$B$90)))) -> 1
A42: Estimate before rounding ($) | B42: =$B$26*$B$32*$B$34*$B$35*$B$36*$B$37*$B$38*$B$39*$B$40*$B$41 -> 3968.8036

Sheet Home_Calculator
A1: Home insurance price and coverage check (live calculator)
A2: Change the blue cells. Price, rebuild-cost check, storm deductibles, roof exposure and a stress test update. A learning model, not a quote.
A4: Your home and policy (edit the blue cells) | E4: Results
A5: State (two-letter code) | B5: FL | E5: Estimate ($ per year, rounded) | F5: =ROUND($B$54,-1) -> 11300
A6: Size (square feet) | B6: 2100 | E6: Typical range: low ($) | F6: =ROUND($B$54*EXP(-Car_Data!$B$123*Home_Data!$B$91),-1) -> 8230
A7: Year built | B7: 1998 | E7: Typical range: high ($) | F7: =ROUND($B$54*EXP(Car_Data!$B$123*Home_Data!$B$91),-1) -> 15520
A8: Roof age (years) | B8: 17 | E8: Your price ($) | F8: =$B$32 -> 3900
A9: Built with | B9: frame | C9: frame or brick | E9: Verdict | F9: =IF(F8>F7,"May be above typical",IF(F8<F6,"Below typical","Inside the typical range")) -> Below typical
A10: How the home is used | B10: own | C10: own, rental, vacation | E10: Share of expected insurer prices below yours | F10: =IF(AND($B$32>0,$B$54>0),NORMSDIST(LN($B$32/$B$54)/Home_Data!$B$91),0.5) -> 0.011778884
A11: Credit rating (blank to skip) | B11: good | C11: poor, fair, good, excellent | E11: Best-case yearly saving ($) | F11: =MAX(0,F8-F6) -> 0
A12: Claims, past 5 years (0 to 3) | B12: 0 | E12: Published state average at $300,000 ($) | F12: =INDEX(Home_Data!$D$5:$D$56,$B$37) -> 8471
A13: House coverage limit ($) | B13: 350000 | C13: Dwelling / Coverage A
A14: Standard deductible ($) | B14: 2500
A15: Personal liability ($000: 100, 300 or 500) | B15: 300 | E15: Is your house cover enough to rebuild?
A16: Hurricane area? | B16: Yes | C16: Yes or No | E16: Estimate | F16: Rebuild cost ($) | G16: Your limit as a share | H16: Shortfall ($)
A17: Wildfire area? | B17: No | C17: Yes or No | E17: Low | F17: =$B$6*Home_Data!$B$95 -> 340200 | G17: =IF(F17>0,$B$13/F17,0) -> 1.0288066 | H17: =MAX(0,F17-$B$13) -> 0
A18: Hail or tornado area? | B18: No | C18: Yes or No | E18: Midpoint | F18: =$B$6*Home_Data!$B$96 -> 588000 | G18: =IF(F18>0,$B$13/F18,0) -> 0.5952381 | H18: =MAX(0,F18-$B$13) -> 238000
A19: In or near a flood zone? | B19: Yes | C19: Yes or No | E19: High | F19: =$B$6*Home_Data!$B$97 -> 735000 | G19: =IF(F19>0,$B$13/F19,0) -> 0.47619048 | H19: =MAX(0,F19-$B$13) -> 385000
A20: Earthquake area? | B20: No | C20: Yes or No | E20: Verdict | F20: =IF($B$13<=0,"Enter a limit",IF($B$13>=F18,"Meets the midpoint estimate",IF($B$13>=0.8*F18,"Close, but below the midpoint",IF($B$13>=F17,"May be short (under 80% of midpoint)","Below even the lowest estimate")))) -> May be short (under 80% of midpoint)
A21: Hurricane deductible (% of house limit; 0 = none) | B21: 0.02 | C21: e.g. 2%
A22: Wind or hail deductible (% of limit; 0 = same as standard) | B22: 0 | E22: Storm deductibles
A23: Roof material | B23: asphalt | C23: asphalt, tile, metal, other | E23: Deductible | F23: Amount you pay first ($) | G23: Note
A24: How the roof is paid | B24: unsure | C24: rcv, acv, sched, unsure | E24: Standard | F24: =$B$14 -> 2500 | G24: fire, theft, water
A25: Roof replacement cost ($) | B25: 20000 | C25: Get a local roofer's quote | E25: Wind or hail | F25: =IF($B$22>0,$B$13*$B$22,$F$24) -> 2500 | G25: percentage of the house limit if set
A26: Extended replacement cost? | B26: No | C26: Yes or No | E26: Hurricane or named storm | F26: =IF($B$21>0,$B$13*$B$21,$F$24) -> 7000 | G26: percentage of the house limit if set
A27: Ordinance or law (code upgrades)? | B27: No | C27: Yes or No | E27: Average wind or hail claim pays | F27: =MAX(0,Home_Data!$B$104-$F$25) -> 11011 | G27: average claim minus the wind deductible
A28: Water backup cover? | B28: No | C28: Yes or No
A29: Separate flood policy? | B29: No | C29: Yes or No | E29: Your roof after a storm
A30: Earthquake cover? | B30: No | C30: Yes or No | E30: Depreciation (straight line over roof life) | F30: =MIN(Home_Data!$B$122,$B$8/IF($B$23="tile",Home_Data!$B$110,IF($B$23="metal",Home_Data!$B$111,IF($B$23="other",Home_Data!$B$112,Home_Data!$B$109)))) -> 0.85
A31: Umbrella policy? | B31: No | C31: Yes or No | E31: If a storm damages the roof | F31: You collect ($) | G31: You pay ($)
A32: What you pay per year ($) | B32: 3900 | E32: Paid at replacement cost | F32: =MAX(0,$B$25-$F$25) -> 17500 | G32: =$B$25-F32 -> 2500
E33: Paid at actual cash value | F33: =MAX(0,$B$25*(1-$F$30)-$F$25) -> 500 | G33: =$B$25-F33 -> 19500
E35: Policy stress test: what would you actually pay?
A36: Price workings (formulas) | E36: Situation | F36: Loss ($) | G36: You collect ($) | H36: You pay ($) | I36: Loss basis
A37: State row | B37: =MATCH($B$5,Home_Data!$B$5:$B$56,0) -> 9 | E37: Typical fire claim | F37: =Home_Data!$B$101 -> 83991 | G37: =MAX(0,F37-$B$14) -> 81491 | H37: =F37-G37 -> 2500 | I37: Average claim (IBHS/III)
A38: Limit used for the curve ($) | B38: =MIN(MAX($B$13,50000),3000000) -> 350000 | E38: House destroyed (rebuild at the midpoint estimate plus code upgrades) | F38: =F18*(1+Home_Data!$B$113) -> 646800 | G38: =MAX(0,MIN($B$13+IF($B$26="Yes",Home_Data!$B$114*$B$13,0)+IF($B$27="Yes",Home_Data!$B$115*$B$13,0),F38-$B$14)) -> 350000 | H38: =F38-G38 -> 296800 | I38: Midpoint estimate + assumed code upgrades
A39: Curve segment | B39: =IFERROR(MIN(3,MAX(1,MATCH($B$38,Home_Data!$C$4:$F$4,1))),1) -> 2 | E39: Typical wind or hail claim | F39: =Home_Data!$B$104 -> 13511 | G39: =MAX(0,F39-$F$25) -> 11011 | H39: =F39-G39 -> 2500 | I39: Average claim
A40: State price at segment start ($) | B40: =INDEX(Home_Data!$C$5:$F$56,$B$37,$B$39) -> 8471 | E40: Hurricane damage (illustrative) | F40: =Home_Data!$B$116 -> 40000 | G40: =MAX(0,F40-$F$26) -> 33000 | H40: =F40-G40 -> 7000 | I40: Illustrative; applies only in hurricane areas
A41: State price at segment end ($) | B41: =INDEX(Home_Data!$C$5:$F$56,$B$37,$B$39+1) -> 11161 | E41: Roof replaced after a storm | F41: =$B$25 -> 20000 | G41: =IF($B$24="rcv",F32,F33) -> 500 | H41: =F41-G41 -> 19500 | I41: Your roof cost; unsure or schedule treated as actual cash value
A42: Segment start limit ($) | B42: =INDEX(Home_Data!$C$4:$F$4,$B$39) -> 300000 | E42: Burst pipe or other water damage | F42: =Home_Data!$B$103 -> 13954 | G42: =MAX(0,F42-$B$14) -> 11454 | H42: =F42-G42 -> 2500 | I42: Average claim
...

Sheet Quote_Requests
A1: Quote request sheets (TX, FL, CA): fill the yellow cells and the model scores itself
A2: Standardized home profiles. Ask an independent agent to price each one with 3 to 5 insurers on the same day, for the standard coverage in the Quote_Kit sheet. Copy the row once per insurer (formulas copy with it). Enter the insurer, date and annual price in the yellow cells.
A4: Standard coverage to request
A5: HO-3, owner-occupied; house cover at the listed limit at replacement cost (record the insurer's figure in the House limit column if it differs); other structures 10%, contents 50%, loss of use 20%; the listed liability and deductible; no optional endorsements; no elective discounts. Record actual property details if the insurer's data differ from the profile.
A7: Profile | B7: State | C7: Sq ft | D7: Year built | E7: Roof age | F7: Build | G7: Use | H7: Claims | I7: House limit ($) | J7: Deductible ($) | K7: Liability ($000) | L7: Credit | M7: Flood | N7: Hurricane | O7: Wildfire | P7: Hail | Q7: Quake | R7: Location guidance | S7: Insurer | T7: Quote date | U7: Annual price ($) | V7: State row | W7: Limit used for the curve ($) | X7: Curve segment | Y7: State price at segment start ($) | Z7: State price at segment end ($) | AA7: Segment start limit ($) | AB7: Segment end limit ($) | AC7: State price at your house limit ($) | AD7: Liability factor | AE7: Deductible factor | AF7: Roof multiple | AG7: House-age multiple | AH7: Construction multiple | AI7: Use multiple | AJ7: Claims multiple | AK7: Credit multiple (1.00 where banned) | AL7: Local-hazard multiple | AM7: Estimate before rounding ($) | AN7: Range low ($) | AO7: Range high ($) | AP7: Inside range? (1 = yes) | AQ7: Error vs. model
A8: TX-1001 | B8: TX | C8: 2400 | D8: 2017 | E8: 8 | F8: brick | G8: own | H8: 1 | I8: 625000 | J8: 5000 | K8: 300 | L8: good | M8: 0 | N8: 0 | O8: 0 | P8: 1 | Q8: 0 | R8: hail or tornado region | V8: =MATCH($B8,Home_Data!$B$5:$B$56,0) -> 43 | W8: =MIN(MAX($I8,50000),3000000) -> 625000 | X8: =IFERROR(MIN(3,MAX(1,MATCH(W8,Home_Data!$C$4:$F$4,1))),1) -> 3 | Y8: =INDEX(Home_Data!$C$5:$F$56,V8,X8) -> 5733 | Z8: =INDEX(Home_Data!$C$5:$F$56,V8,X8+1) -> 7858 | AA8: =INDEX(Home_Data!$C$4:$F$4,X8) -> 400000 | AB8: =INDEX(Home_Data!$C$4:$F$4,X8+1) -> 600000 | AC8: =IF($I8<200000,INDEX(Home_Data!$C$5:$F$56,V8,1)*(MAX($I8,Home_Data!$B$90)/200000)^Home_Data!$B$89,Y8*(W8/AA8)^(LN(Z8/Y8)/LN(AB8/AA8))) -> 8111.442 | AD8: =IF($K8=100,Home_Data!$B$67,IF($K8=500,Home_Data!$B$69,Home_Data!$B$68)) -> 1 | AE8: =IF($J8<=Home_Data!$B$61,Home_Data!$B$64,IF($J8>=Home_Data!$B$63,Home_Data!$B$66,IF($J8<=Home_Data!$B$62,Home_Data!$B$64+(Home_Data!$B$65-Home_Data!$B$64)*(LN($J8)-LN(Home_Data!$B$61))/(LN(Home_Data!$B$62)-LN(Home_Data!$B$61)),Home_Data!$B$65+(Home_Data!$B$66-Home_Data!$B$65)*(LN($J8)-LN(Home_Data!$B$62))/(LN(Home_Data!$B$63)-LN(Home_Data!$B$62))))) -> 0.84 | AF8: =IF($E8>=20,Home_Data!$B$80,IF($E8>=10,Home_Data!$B$79,1)) -> 1 | AG8: =IF($D8<1960,Home_Data!$B$81,IF($D8<1980,Home_Data!$B$82,IF($D8>=2000,Home_Data!$B$83,1))) -> 0.95 | AH8: =IF($F8="brick",Home_Data!$B$78,1) -> 0.98 | AI8: =IF($G8="rental",Home_Data!$B$84,IF($G8="vacation",Home_Data!$B$85,1)) -> 1 | AJ8: =INDEX(Home_Data!$B$70:$B$73,MIN(3,MAX(0,$H8))+1) -> 1.16 | AK8: =IF(INDEX(Home_Data!$H$5:$H$56,V8)="Yes",1,IF($L8="poor",Home_Data!$B$74,IF($L8="fair",Home_Data!$B$75,IF($L8="excellent",Home_Data!$B$77,Home_Data!$B$76)))) -> 1 | AL8: =IF(($N8=1),Home_Data!$B$86,1)*IF(($O8=1),Home_Data!$B$87,1)*IF(($P8=1),Home_Data!$B$88,1) -> 1.08 | AM8: =AC8*AD8*AE8*AF8*AG8*AH8*AI8*AJ8*AK8*AL8 -> 7947.1018 | AN8: =AM8*EXP(-Car_Data!$B$123*Home_Data!$B$91) -> 5788.0597 | AO8: =AM8*EXP(Car_Data!$B$123*Home_Data!$B$91) -> 10911.502 | AP8: =IF($U8>0,IF(AND($U8>=AN8,$U8<=AO8),1,0),"") | AQ8: =IF($U8>0,$U8/AM8-1,"")
A9: TX-1002 | B9: TX | C9: 1300 | D9: 2004 | E9: 22 | F9: frame | G9: own | H9: 1 | I9: 310000 | J9: 2500 | K9: 300 | L9: excellent | M9: 0 | N9: 1 | O9: 0 | P9: 0 | Q9: 0 | R9: coastal or hurricane-exposed county | V9: =MATCH($B9,Home_Data!$B$5:$B$56,0) -> 43 | W9: =MIN(MAX($I9,50000),3000000) -> 310000 | X9: =IFERROR(MIN(3,MAX(1,MATCH(W9,Home_Data!$C$4:$F$4,1))),1) -> 2 | Y9: =INDEX(Home_Data!$C$5:$F$56,V9,X9) -> 4582 | Z9: =INDEX(Home_Data!$C$5:$F$56,V9,X9+1) -> 5733 | AA9: =INDEX(Home_Data!$C$4:$F$4,X9) -> 300000 | AB9: =INDEX(Home_Data!$C$4:$F$4,X9+1) -> 400000 | AC9: =IF($I9<200000,INDEX(Home_Data!$C$5:$F$56,V9,1)*(MAX($I9,Home_Data!$B$90)/200000)^Home_Data!$B$89,Y9*(W9/AA9)^(LN(Z9/Y9)/LN(AB9/AA9))) -> 4700.5463 | AD9: =IF($K9=100,Home_Data!$B$67,IF($K9=500,Home_Data!$B$69,Home_Data!$B$68)) -> 1 | AE9: =IF($J9<=Home_Data!$B$61,Home_Data!$B$64,IF($J9>=Home_Data!$B$63,Home_Data!$B$66,IF($J9<=Home_Data!$B$62,Home_Data!$B$64+(Home_Data!$B$65-Home_Data!$B$64)*(LN($J9)-LN(Home_Data!$B$61))/(LN(Home_Data!$B$62)-LN(Home_Data!$B$61)),Home_Data!$B$65+(Home_Data!$B$66-Home_Data!$B$65)*(LN($J9)-LN(Home_Data!$B$62))/(LN(Home_Data!$B$63)-LN(Home_Data!$B$62))))) -> 0.91 | AF9: =IF($E9>=20,Home_Data!$B$80,IF($E9>=10,Home_Data!$B$79,1)) -> 1.3 | AG9: =IF($D9<1960,Home_Data!$B$81,IF($D9<1980,Home_Data!$B$82,IF($D9>=2000,Home_Data!$B$83,1))) -> 0.95 | AH9: =IF($F9="brick",Home_Data!$B$78,1) -> 1 | AI9: =IF($G9="rental",Home_Data!$B$84,IF($G9="vacation",Home_Data!$B$85,1)) -> 1 | AJ9: =INDEX(Home_Data!$B$70:$B$73,MIN(3,MAX(0,$H9))+1) -> 1.16 | AK9: =IF(INDEX(Home_Data!$H$5:$H$56,V9)="Yes",1,IF($L9="poor",Home_Data!$B$74,IF($L9="fair",Home_Data!$B$75,IF($L9="excellent",Home_Data!$B$77,Home_Data!$B$76)))) -> 0.89 | AL9: =IF(($N9=1),Home_Data!$B$86,1)*IF(($O9=1),Home_Data!$B$87,1)*IF(($P9=1),Home_Data!$B$88,1) -> 1.15 | AM9: =AC9*AD9*AE9*AF9*AG9*AH9*AI9*AJ9*AK9*AL9 -> 6271.9491 | AN9: =AM9*EXP(-Car_Data!$B$123*Home_Data!$B$91) -> 4568.0069 | AO9: =AM9*EXP(Car_Data!$B$123*Home_Data!$B$91) -> 8611.4899 | AP9: =IF($U9>0,IF(AND($U9>=AN9,$U9<=AO9),1,0),"") | AQ9: =IF($U9>0,$U9/AM9-1,"")
A10: TX-1003 | B10: TX | C10: 3100 | D10: 2017 | E10: 0 | F10: frame | G10: own | H10: 2 | I10: 660000 | J10: 1000 | K10: 300 | L10: excellent | M10: 0 | N10: 0 | O10: 0 | P10: 0 | Q10: 0 | R10: inland, no special hazard | V10: =MATCH($B10,Home_Data!$B$5:$B$56,0) -> 43 | W10: =MIN(MAX($I10,50000),3000000) -> 660000 | X10: =IFERROR(MIN(3,MAX(1,MATCH(W10,Home_Data!$C$4:$F$4,1))),1) -> 3 | Y10: =INDEX(Home_Data!$C$5:$F$56,V10,X10) -> 5733 | Z10: =INDEX(Home_Data!$C$5:$F$56,V10,X10+1) -> 7858 | AA10: =INDEX(Home_Data!$C$4:$F$4,X10) -> 400000 | AB10: =INDEX(Home_Data!$C$4:$F$4,X10+1) -> 600000 | AC10: =IF($I10<200000,INDEX(Home_Data!$C$5:$F$56,V10,1)*(MAX($I10,Home_Data!$B$90)/200000)^Home_Data!$B$89,Y10*(W10/AA10)^(LN(Z10/Y10)/LN(AB10/AA10))) -> 8462.5127 | AD10: =IF($K10=100,Home_Data!$B$67,IF($K10=500,Home_Data!$B$69,Home_Data!$B$68)) -> 1 | AE10: =IF($J10<=Home_Data!$B$61,Home_Data!$B$64,IF($J10>=Home_Data!$B$63,Home_Data!$B$66,IF($J10<=Home_Data!$B$62,Home_Data!$B$64+(Home_Data!$B$65-Home_Data!$B$64)*(LN($J10)-LN(Home_Data!$B$61))/(LN(Home_Data!$B$62)-LN(Home_Data!$B$61)),Home_Data!$B$65+(Home_Data!$B$66-Home_Data!$B$65)*(LN($J10)-LN(Home_Data!$B$62))/(LN(Home_Data!$B$63)-LN(Home_Data!$B$62))))) -> 1 | AF10: =IF($E10>=20,Home_Data!$B$80,IF($E10>=10,Home_Data!$B$79,1)) -> 1 | AG10: =IF($D10<1960,Home_Data!$B$81,IF($D10<1980,Home_Data!$B$82,IF($D10>=2000,Home_Data!$B$83,1))) -> 0.95 | AH10: =IF($F10="brick",Home_Data!$B$78,1) -> 1 | AI10: =IF($G10="rental",Home_Data!$B$84,IF($G10="vacation",Home_Data!$B$85,1)) -> 1 | AJ10: =INDEX(Home_Data!$B$70:$B$73,MIN(3,MAX(0,$H10))+1) -> 1.29 | AK10: =IF(INDEX(Home_Data!$H$5:$H$56,V10)="Yes",1,IF($L10="poor",Home_Data!$B$74,IF($L10="fair",Home_Data!$B$75,IF($L10="excellent",Home_Data!$B$77,Home_Data!$B$76)))) -> 0.89 | AL10: =IF(($N10=1),Home_Data!$B$86,1)*IF(($O10=1),Home_Data!$B$87,1)*IF(($P10=1),Home_Data!$B$88,1) -> 1 | AM10: =AC10*AD10*AE10*AF10*AG10*AH10*AI10*AJ10*AK10*AL10 -> 9230.0203 | AN10: =AM10*EXP(-Car_Data!$B$123*Home_Data!$B$91) -> 6722.4392 | AO10: =AM10*EXP(Car_Data!$B$123*Home_Data!$B$91) -> 12672.971 | AP10: =IF($U10>0,IF(AND($U10>=AN10,$U10<=AO10),1,0),"") | AQ10: =IF($U10>0,$U10/AM10-1,"")
A11: TX-1004 | B11: TX | C11: 2500 | D11: 2010 | E11: 11 | F11: frame | G11: own | H11: 0 | I11: 685000 | J11: 2500 | K11: 500 | L11: good | M11: 0 | N11: 1 | O11: 0 | P11: 1 | Q11: 0 | R11: coastal or hurricane-exposed county; hail or tornado region | V11: =MATCH($B11,Home_Data!$B$5:$B$56,0) -> 43 | W11: =MIN(MAX($I11,50000),3000000) -> 685000 | X11: =IFERROR(MIN(3,MAX(1,MATCH(W11,Home_Data!$C$4:$F$4,1))),1) -> 3 | Y11: =INDEX(Home_Data!$C$5:$F$56,V11,X11) -> 5733 | Z11: =INDEX(Home_Data!$C$5:$F$56,V11,X11+1) -> 7858 | AA11: =INDEX(Home_Data!$C$4:$F$4,X11) -> 400000 | AB11: =INDEX(Home_Data!$C$4:$F$4,X11+1) -> 600000 | AC11: =IF($I11<200000,INDEX(Home_Data!$C$5:$F$56,V11,1)*(MAX($I11,Home_Data!$B$90)/200000)^Home_Data!$B$89,Y11*(W11/AA11)^(LN(Z11/Y11)/LN(AB11/AA11))) -> 8710.7409 | AD11: =IF($K11=100,Home_Data!$B$67,IF($K11=500,Home_Data!$B$69,Home_Data!$B$68)) -> 1.005 | AE11: =IF($J11<=Home_Data!$B$61,Home_Data!$B$64,IF($J11>=Home_Data!$B$63,Home_Data!$B$66,IF($J11<=Home_Data!$B$62,Home_Data!$B$64+(Home_Data!$B$65-Home_Data!$B$64)*(LN($J11)-LN(Home_Data!$B$61))/(LN(Home_Data!$B$62)-LN(Home_Data!$B$61)),Home_Data!$B$65+(Home_Data!$B$66-Home_Data!$B$65)*(LN($J11)-LN(Home_Data!$B$62))/(LN(Home_Data!$B$63)-LN(Home_Data!$B$62))))) -> 0.91 | AF11: =IF($E11>=20,Home_Data!$B$80,IF($E11>=10,Home_Data!$B$79,1)) -> 1.1 | AG11: =IF($D11<1960,Home_Data!$B$81,IF($D11<1980,Home_Data!$B$82,IF($D11>=2000,Home_Data!$B$83,1))) -> 0.95 | AH11: =IF($F11="brick",Home_Data!$B$78,1) -> 1 | AI11: =IF($G11="rental",Home_Data!$B$84,IF($G11="vacation",Home_Data!$B$85,1)) -> 1 | AJ11: =INDEX(Home_Data!$B$70:$B$73,MIN(3,MAX(0,$H11))+1) -> 1 | AK11: =IF(INDEX(Home_Data!$H$5:$H$56,V11)="Yes",1,IF($L11="poor",Home_Data!$B$74,IF($L11="fair",Home_Data!$B$75,IF($L11="excellent",Home_Data!$B$77,Home_Data!$B$76)))) -> 1 | AL11: =IF(($N11=1),Home_Data!$B$86,1)*IF(($O11=1),Home_Data!$B$87,1)*IF(($P11=1),Home_Data!$B$88,1) -> 1.242 | AM11: =AC11*AD11*AE11*AF11*AG11*AH11*AI11*AJ11*AK11*AL11 -> 10339.521 | AN11: =AM11*EXP(-Car_Data!$B$123*Home_Data!$B$91) -> 7530.5148 | AO11: =AM11*EXP(Car_Data!$B$123*Home_Data!$B$91) -> 14196.334 | AP11: =IF($U11>0,IF(AND($U11>=AN11,$U11<=AO11),1,0),"") | AQ11: =IF($U11>0,$U11/AM11-1,"")
A12: TX-1005 | B12: TX | C12: 3750 | D12: 1987 | E12: 23 | F12: brick | G12: own | H12: 0 | I12: 905000 | J12: 5000 | K12: 300 | L12: fair | M12: 0 | N12: 0 | O12: 0 | P12: 1 | Q12: 0 | R12: hail or tornado region | V12: =MATCH($B12,Home_Data!$B$5:$B$56,0) -> 43 | W12: =MIN(MAX($I12,50000),3000000) -> 905000 | X12: =IFERROR(MIN(3,MAX(1,MATCH(W12,Home_Data!$C$4:$F$4,1))),1) -> 3 | Y12: =INDEX(Home_Data!$C$5:$F$56,V12,X12) -> 5733 | Z12: =INDEX(Home_Data!$C$5:$F$56,V12,X12+1) -> 7858 | AA12: =INDEX(Home_Data!$C$4:$F$4,X12) -> 400000 | AB12: =INDEX(Home_Data!$C$4:$F$4,X12+1) -> 600000 | AC12: =IF($I12<200000,INDEX(Home_Data!$C$5:$F$56,V12,1)*(MAX($I12,Home_Data!$B$90)/200000)^Home_Data!$B$89,Y12*(W12/AA12)^(LN(Z12/Y12)/LN(AB12/AA12))) -> 10817.156 | AD12: =IF($K12=100,Home_Data!$B$67,IF($K12=500,Home_Data!$B$69,Home_Data!$B$68)) -> 1 | AE12: =IF($J12<=Home_Data!$B$61,Home_Data!$B$64,IF($J12>=Home_Data!$B$63,Home_Data!$B$66,IF($J12<=Home_Data!$B$62,Home_Data!$B$64+(Home_Data!$B$65-Home_Data!$B$64)*(LN($J12)-LN(Home_Data!$B$61))/(LN(Home_Data!$B$62)-LN(Home_Data!$B$61)),Home_Data!$B$65+(Home_Data!$B$66-Home_Data!$B$65)*(LN($J12)-LN(Home_Data!$B$62))/(LN(Home_Data!$B$63)-LN(Home_Data!$B$62))))) -> 0.84 | AF12: =IF($E12>=20,Home_Data!$B$80,IF($E12>=10,Home_Data!$B$79,1)) -> 1.3 | AG12: =IF($D12<1960,Home_Data!$B$81,IF($D12<1980,Home_Data!$B$82,IF($D12>=2000,Home_Data!$B$83,1))) -> 1 | AH12: =IF($F12="brick",Home_Data!$B$78,1) -> 0.98 | AI12: =IF($G12="rental",Home_Data!$B$84,IF($G12="vacation",Home_Data!$B$85,1)) -> 1 | AJ12: =INDEX(Home_Data!$B$70:$B$73,MIN(3,MAX(0,$H12))+1) -> 1 | AK12: =IF(INDEX(Home_Data!$H$5:$H$56,V12)="Yes",1,IF($L12="poor",Home_Data!$B$74,IF($L12="fair",Home_Data!$B$75,IF($L12="excellent",Home_Data!$B$77,Home_Data!$B$76)))) -> 1.07 | AL12: =IF(($N12=1),Home_Data!$B$86,1)*IF(($O12=1),Home_Data!$B$87,1)*IF(($P12=1),Home_Data!$B$88,1) -> 1.08 | AM12: =AC12*AD12*AE12*AF12*AG12*AH12*AI12*AJ12*AK12*AL12 -> 13377.327 | AN12: =AM12*EXP(-Car_Data!$B$123*Home_Data!$B$91) -> 9743.0193 | AO12: =AM12*EXP(Car_Data!$B$123*Home_Data!$B$91) -> 18367.291 | AP12: =IF($U12>0,IF(AND($U12>=AN12,$U12<=AO12),1,0),"") | AQ12: =IF($U12>0,$U12/AM12-1,"")
A13: TX-1006 | B13: TX | C13: 3150 | D13: 1978 | E13: 21 | F13: frame | G13: own | H13: 0 | I13: 825000 | J13: 5000 | K13: 300 | L13: good | M13: 0 | N13: 1 | O13: 0 | P13: 1 | Q13: 0 | R13: coastal or hurricane-exposed county; hail or tornado region | V13: =MATCH($B13,Home_Data!$B$5:$B$56,0) -> 43 | W13: =MIN(MAX($I13,50000),3000000) -> 825000 | X13: =IFERROR(MIN(3,MAX(1,MATCH(W13,Home_Data!$C$4:$F$4,1))),1) -> 3 | Y13: =INDEX(Home_Data!$C$5:$F$56,V13,X13) -> 5733 | Z13: =INDEX(Home_Data!$C$5:$F$56,V13,X13+1) -> 7858 | AA13: =INDEX(Home_Data!$C$4:$F$4,X13) -> 400000 | AB13: =INDEX(Home_Data!$C$4:$F$4,X13+1) -> 600000 | AC13: =IF($I13<200000,INDEX(Home_Data!$C$5:$F$56,V13,1)*(MAX($I13,Home_Data!$B$90)/200000)^Home_Data!$B$89,Y13*(W13/AA13)^(LN(Z13/Y13)/LN(AB13/AA13))) -> 10066.011 | AD13: =IF($K13=100,Home_Data!$B$67,IF($K13=500,Home_Data!$B$69,Home_Data!$B$68)) -> 1 | AE13: =IF($J13<=Home_Data!$B$61,Home_Data!$B$64,IF($J13>=Home_Data!$B$63,Home_Data!$B$66,IF($J13<=Home_Data!$B$62,Home_Data!$B$64+(Home_Data!$B$65-Home_Data!$B$64)*(LN($J13)-LN(Home_Data!$B$61))/(LN(Home_Data!$B$62)-LN(Home_Data!$B$61)),Home_Data!$B$65+(Home_Data!$B$66-Home_Data!$B$65)*(LN($J13)-LN(Home_Data!$B$62))/(LN(Home_Data!$B$63)-LN(Home_Data!$B$62))))) -> 0.84 | AF13: =IF($E13>=20,Home_Data!$B$80,IF($E13>=10,Home_Data!$B$79,1)) -> 1.3 | AG13: =IF($D13<1960,Home_Data!$B$81,IF($D13<1980,Home_Data!$B$82,IF($D13>=2000,Home_Data!$B$83,1))) -> 1.08 | AH13: =IF($F13="brick",Home_Data!$B$78,1) -> 1 | AI13: =IF($G13="rental",Home_Data!$B$84,IF($G13="vacation",Home_Data!$B$85,1)) -> 1 | AJ13: =INDEX(Home_Data!$B$70:$B$73,MIN(3,MAX(0,$H13))+1) -> 1 | AK13: =IF(INDEX(Home_Data!$H$5:$H$56,V13)="Yes",1,IF($L13="poor",Home_Data!$B$74,IF($L13="fair",Home_Data!$B$75,IF($L13="excellent",Home_Data!$B$77,Home_Data!$B$76)))) -> 1 | AL13: =IF(($N13=1),Home_Data!$B$86,1)*IF(($O13=1),Home_Data!$B$87,1)*IF(($P13=1),Home_Data!$B$88,1) -> 1.242 | AM13: =AC13*AD13*AE13*AF13*AG13*AH13*AI13*AJ13*AK13*AL13 -> 14744.342 | AN13: =AM13*EXP(-Car_Data!$B$123*Home_Data!$B$91) -> 10738.648 | AO13: =AM13*EXP(Car_Data!$B$123*Home_Data!$B$91) -> 20244.225 | AP13: =IF($U13>0,IF(AND($U13>=AN13,$U13<=AO13),1,0),"") | AQ13: =IF($U13>0,$U13/AM13-1,"")
A14: TX-1007 | B14: TX | C14: 1200 | D14: 1976 | E14: 16 | F14: frame | G14: own | H14: 0 | I14: 295000 | J14: 1000 | K14: 100 | L14: good | M14: 0 | N14: 0 | O14: 0 | P14: 1 | Q14: 0 | R14: hail or tornado region | V14: =MATCH($B14,Home_Data!$B$5:$B$56,0) -> 43 | W14: =MIN(MAX($I14,50000),3000000) -> 295000 | X14: =IFERROR(MIN(3,MAX(1,MATCH(W14,Home_Data!$C$4:$F$4,1))),1) -> 1 | Y14: =INDEX(Home_Data!$C$5:$F$56,V14,X14) -> 3294 | Z14: =INDEX(Home_Data!$C$5:$F$56,V14,X14+1) -> 4582 | AA14: =INDEX(Home_Data!$C$4:$F$4,X14) -> 200000 | AB14: =INDEX(Home_Data!$C$4:$F$4,X14+1) -> 300000 | AC14: =IF($I14<200000,INDEX(Home_Data!$C$5:$F$56,V14,1)*(MAX($I14,Home_Data!$B$90)/200000)^Home_Data!$B$89,Y14*(W14/AA14)^(LN(Z14/Y14)/LN(AB14/AA14))) -> 4519.7435 | AD14: =IF($K14=100,Home_Data!$B$67,IF($K14=500,Home_Data!$B$69,Home_Data!$B$68)) -> 0.991 | AE14: =IF($J14<=Home_Data!$B$61,Home_Data!$B$64,IF($J14>=Home_Data!$B$63,Home_Data!$B$66,IF($J14<=Home_Data!$B$62,Home_Data!$B$64+(Home_Data!$B$65-Home_Data!$B$64)*(LN($J14)-LN(Home_Data!$B$61))/(LN(Home_Data!$B$62)-LN(Home_Data!$B$61)),Home_Data!$B$65+(Home_Data!$B$66-Home_Data!$B$65)*(LN($J14)-LN(Home_Data!$B$62))/(LN(Home_Data!$B$63)-LN(Home_Data!$B$62))))) -> 1 | AF14: =IF($E14>=20,Home_Data!$B$80,IF($E14>=10,Home_Data!$B$79,1)) -> 1.1 | AG14: =IF($D14<1960,Home_Data!$B$81,IF($D14<1980,Home_Data!$B$82,IF($D14>=2000,Home_Data!$B$83,1))) -> 1.08 | AH14: =IF($F14="brick",Home_Data!$B$78,1) -> 1 | AI14: =IF($G14="rental",Home_Data!$B$84,IF($G14="vacation",Home_Data!$B$85,1)) -> 1 | AJ14: =INDEX(Home_Data!$B$70:$B$73,MIN(3,MAX(0,$H14))+1) -> 1 | AK14: =IF(INDEX(Home_Data!$H$5:$H$56,V14)="Yes",1,IF($L14="poor",Home_Data!$B$74,IF($L14="fair",Home_Data!$B$75,IF($L14="excellent",Home_Data!$B$77,Home_Data!$B$76)))) -> 1 | AL14: =IF(($N14=1),Home_Data!$B$86,1)*IF(($O14=1),Home_Data!$B$87,1)*IF(($P14=1),Home_Data!$B$88,1) -> 1.08 | AM14: =AC14*AD14*AE14*AF14*AG14*AH14*AI14*AJ14*AK14*AL14 -> 5746.8206 | AN14: =AM14*EXP(-Car_Data!$B$123*Home_Data!$B$91) -> 4185.5435 | AO14: =AM14*EXP(Car_Data!$B$123*Home_Data!$B$91) -> 7890.4798 | AP14: =IF($U14>0,IF(AND($U14>=AN14,$U14<=AO14),1,0),"") | AQ14: =IF($U14>0,$U14/AM14-1,"")
A15: TX-1008 | B15: TX | C15: 3750 | D15: 2018 | E15: 1 | F15: frame | G15: own | H15: 0 | I15: 1035000 | J15: 1000 | K15: 300 | L15: good | M15: 0 | N15: 0 | O15: 0 | P15: 0 | Q15: 0 | R15: inland, no special hazard | V15: =MATCH($B15,Home_Data!$B$5:$B$56,0) -> 43 | W15: =MIN(MAX($I15,50000),3000000) -> 1035000 | X15: =IFERROR(MIN(3,MAX(1,MATCH(W15,Home_Data!$C$4:$F$4,1))),1) -> 3 | Y15: =INDEX(Home_Data!$C$5:$F$56,V15,X15) -> 5733 | Z15: =INDEX(Home_Data!$C$5:$F$56,V15,X15+1) -> 7858 | AA15: =INDEX(Home_Data!$C$4:$F$4,X15) -> 400000 | AB15: =INDEX(Home_Data!$C$4:$F$4,X15+1) -> 600000 | AC15: =IF($I15<200000,INDEX(Home_Data!$C$5:$F$56,V15,1)*(MAX($I15,Home_Data!$B$90)/200000)^Home_Data!$B$89,Y15*(W15/AA15)^(LN(Z15/Y15)/LN(AB15/AA15))) -> 12007.187 | AD15: =IF($K15=100,Home_Data!$B$67,IF($K15=500,Home_Data!$B$69,Home_Data!$B$68)) -> 1 | AE15: =IF($J15<=Home_Data!$B$61,Home_Data!$B$64,IF($J15>=Home_Data!$B$63,Home_Data!$B$66,IF($J15<=Home_Data!$B$62,Home_Data!$B$64+(Home_Data!$B$65-Home_Data!$B$64)*(LN($J15)-LN(Home_Data!$B$61))/(LN(Home_Data!$B$62)-LN(Home_Data!$B$61)),Home_Data!$B$65+(Home_Data!$B$66-Home_Data!$B$65)*(LN($J15)-LN(Home_Data!$B$62))/(LN(Home_Data!$B$63)-LN(Home_Data!$B$62))))) -> 1 | AF15: =IF($E15>=20,Home_Data!$B$80,IF($E15>=10,Home_Data!$B$79,1)) -> 1 | AG15: =IF($D15<1960,Home_Data!$B$81,IF($D15<1980,Home_Data!$B$82,IF($D15>=2000,Home_Data!$B$83,1))) -> 0.95 | AH15: =IF($F15="brick",Home_Data!$B$78,1) -> 1 | AI15: =IF($G15="rental",Home_Data!$B$84,IF($G15="vacation",Home_Data!$B$85,1)) -> 1 | AJ15: =INDEX(Home_Data!$B$70:$B$73,MIN(3,MAX(0,$H15))+1) -> 1 | AK15: =IF(INDEX(Home_Data!$H$5:$H$56,V15)="Yes",1,IF($L15="poor",Home_Data!$B$74,IF($L15="fair",Home_Data!$B$75,IF($L15="excellent",Home_Data!$B$77,Home_Data!$B$76)))) -> 1 | AL15: =IF(($N15=1),Home_Data!$B$86,1)*IF(($O15=1),Home_Data!$B$87,1)*IF(($P15=1),Home_Data!$B$88,1) -> 1 | AM15: =AC15*AD15*AE15*AF15*AG15*AH15*AI15*AJ15*AK15*AL15 -> 11406.828 | AN15: =AM15*EXP(-Car_Data!$B$123*Home_Data!$B$91) -> 8307.8587 | AO15: =AM15*EXP(Car_Data!$B$123*Home_Data!$B$91) -> 15661.763 | AP15: =IF($U15>0,IF(AND($U15>=AN15,$U15<=AO15),1,0),"") | AQ15: =IF($U15>0,$U15/AM15-1,"")
A16: TX-1009 | B16: TX | C16: 1500 | D16: 1972 | E16: 1 | F16: frame | G16: own | H16: 0 | I16: 335000 | J16: 1000 | K16: 100 | L16: good | M16: 0 | N16: 0 | O16: 1 | P16: 1 | Q16: 0 | R16: hail or tornado region; wildfire-exposed area | V16: =MATCH($B16,Home_Data!$B$5:$B$56,0) -> 43 | W16: =MIN(MAX($I16,50000),3000000) -> 335000 | X16: =IFERROR(MIN(3,MAX(1,MATCH(W16,Home_Data!$C$4:$F$4,1))),1) -> 2 | Y16: =INDEX(Home_Data!$C$5:$F$56,V16,X16) -> 4582 | Z16: =INDEX(Home_Data!$C$5:$F$56,V16,X16+1) -> 5733 | AA16: =INDEX(Home_Data!$C$4:$F$4,X16) -> 300000 | AB16: =INDEX(Home_Data!$C$4:$F$4,X16+1) -> 400000 | AC16: =IF($I16<200000,INDEX(Home_Data!$C$5:$F$56,V16,1)*(MAX($I16,Home_Data!$B$90)/200000)^Home_Data!$B$89,Y16*(W16/AA16)^(LN(Z16/Y16)/LN(AB16/AA16))) -> 4993.2967 | AD16: =IF($K16=100,Home_Data!$B$67,IF($K16=500,Home_Data!$B$69,Home_Data!$B$68)) -> 0.991 | AE16: =IF($J16<=Home_Data!$B$61,Home_Data!$B$64,IF($J16>=Home_Data!$B$63,Home_Data!$B$66,IF($J16<=Home_Data!$B$62,Home_Data!$B$64+(Home_Data!$B$65-Home_Data!$B$64)*(LN($J16)-LN(Home_Data!$B$61))/(LN(Home_Data!$B$62)-LN(Home_Data!$B$61)),Home_Data!$B$65+(Home_Data!$B$66-Home_Data!$B$65)*(LN($J16)-LN(Home_Data!$B$62))/(LN(Home_Data!$B$63)-LN(Home_Data!$B$62))))) -> 1 | AF16: =IF($E16>=20,Home_Data!$B$80,IF($E16>=10,Home_Data!$B$79,1)) -> 1 | AG16: =IF($D16<1960,Home_Data!$B$81,IF($D16<1980,Home_Data!$B$82,IF($D16>=2000,Home_Data!$B$83,1))) -> 1.08 | AH16: =IF($F16="brick",Home_Data!$B$78,1) -> 1 | AI16: =IF($G16="rental",Home_Data!$B$84,IF($G16="vacation",Home_Data!$B$85,1)) -> 1 | AJ16: =INDEX(Home_Data!$B$70:$B$73,MIN(3,MAX(0,$H16))+1) -> 1 | AK16: =IF(INDEX(Home_Data!$H$5:$H$56,V16)="Yes",1,IF($L16="poor",Home_Data!$B$74,IF($L16="fair",Home_Data!$B$75,IF($L16="excellent",Home_Data!$B$77,Home_Data!$B$76)))) -> 1 | AL16: =IF(($N16=1),Home_Data!$B$86,1)*IF(($O16=1),Home_Data!$B$87,1)*IF(($P16=1),Home_Data!$B$88,1) -> 1.242 | AM16: =AC16*AD16*AE16*AF16*AG16*AH16*AI16*AJ16*AK16*AL16 -> 6637.5282 | AN16: =AM16*EXP(-Car_Data!$B$123*Home_Data!$B$91) -> 4834.2667 | AO16: =AM16*EXP(Car_Data!$B$123*Home_Data!$B$91) -> 9113.436 | AP16: =IF($U16>0,IF(AND($U16>=AN16,$U16<=AO16),1,0),"") | AQ16: =IF($U16>0,$U16/AM16-1,"")
A17: TX-1010 | B17: TX | C17: 2500 | D17: 1999 | E17: 6 | F17: frame | G17: own | H17: 0 | I17: 545000 | J17: 1000 | K17: 300 | L17: excellent | M17: 0 | N17: 0 | O17: 0 | P17: 0 | Q17: 0 | R17: inland, no special hazard | V17: =MATCH($B17,Home_Data!$B$5:$B$56,0) -> 43 | W17: =MIN(MAX($I17,50000),3000000) -> 545000 | X17: =IFERROR(MIN(3,MAX(1,MATCH(W17,Home_Data!$C$4:$F$4,1))),1) -> 3 | Y17: =INDEX(Home_Data!$C$5:$F$56,V17,X17) -> 5733 | Z17: =INDEX(Home_Data!$C$5:$F$56,V17,X17+1) -> 7858 | AA17: =INDEX(Home_Data!$C$4:$F$4,X17) -> 400000 | AB17: =INDEX(Home_Data!$C$4:$F$4,X17+1) -> 600000 | AC17: =IF($I17<200000,INDEX(Home_Data!$C$5:$F$56,V17,1)*(MAX($I17,Home_Data!$B$90)/200000)^Home_Data!$B$89,Y17*(W17/AA17)^(LN(Z17/Y17)/LN(AB17/AA17))) -> 7291.9414 | AD17: =IF($K17=100,Home_Data!$B$67,IF($K17=500,Home_Data!$B$69,Home_Data!$B$68)) -> 1 | AE17: =IF($J17<=Home_Data!$B$61,Home_Data!$B$64,IF($J17>=Home_Data!$B$63,Home_Data!$B$66,IF($J17<=Home_Data!$B$62,Home_Data!$B$64+(Home_Data!$B$65-Home_Data!$B$64)*(LN($J17)-LN(Home_Data!$B$61))/(LN(Home_Data!$B$62)-LN(Home_Data!$B$61)),Home_Data!$B$65+(Home_Data!$B$66-Home_Data!$B$65)*(LN($J17)-LN(Home_Data!$B$62))/(LN(Home_Data!$B$63)-LN(Home_Data!$B$62))))) -> 1 | AF17: =IF($E17>=20,Home_Data!$B$80,IF($E17>=10,Home_Data!$B$79,1)) -> 1 | AG17: =IF($D17<1960,Home_Data!$B$81,IF($D17<1980,Home_Data!$B$82,IF($D17>=2000,Home_Data!$B$83,1))) -> 1 | AH17: =IF($F17="brick",Home_Data!$B$78,1) -> 1 | AI17: =IF($G17="rental",Home_Data!$B$84,IF($G17="vacation",Home_Data!$B$85,1)) -> 1 | AJ17: =INDEX(Home_Data!$B$70:$B$73,MIN(3,MAX(0,$H17))+1) -> 1 | AK17: =IF(INDEX(Home_Data!$H$5:$H$56,V17)="Yes",1,IF($L17="poor",Home_Data!$B$74,IF($L17="fair",Home_Data!$B$75,IF($L17="excellent",Home_Data!$B$77,Home_Data!$B$76)))) -> 0.89 | AL17: =IF(($N17=1),Home_Data!$B$86,1)*IF(($O17=1),Home_Data!$B$87,1)*IF(($P17=1),Home_Data!$B$88,1) -> 1 | AM17: =AC17*AD17*AE17*AF17*AG17*AH17*AI17*AJ17*AK17*AL17 -> 6489.8279 | AN17: =AM17*EXP(-Car_Data!$B$123*Home_Data!$B$91) -> 4726.6931 | AO17: =AM17*EXP(Car_Data!$B$123*Home_Data!$B$91) -> 8910.6411 | AP17: =IF($U17>0,IF(AND($U17>=AN17,$U17<=AO17),1,0),"") | AQ17: =IF($U17>0,$U17/AM17-1,"")
A18: TX-1011 | B18: TX | C18: 3200 | D18: 2013 | E18: 8 | F18: frame | G18: own | H18: 0 | I18: 905000 | J18: 1000 | K18: 300 | L18: good | M18: 0 | N18: 0 | O18: 1 | P18: 0 | Q18: 0 | R18: wildfire-exposed area | V18: =MATCH($B18,Home_Data!$B$5:$B$56,0) -> 43 | W18: =MIN(MAX($I18,50000),3000000) -> 905000 | X18: =IFERROR(MIN(3,MAX(1,MATCH(W18,Home_Data!$C$4:$F$4,1))),1) -> 3 | Y18: =INDEX(Home_Data!$C$5:$F$56,V18,X18) -> 5733 | Z18: =INDEX(Home_Data!$C$5:$F$56,V18,X18+1) -> 7858 | AA18: =INDEX(Home_Data!$C$4:$F$4,X18) -> 400000 | AB18: =INDEX(Home_Data!$C$4:$F$4,X18+1) -> 600000 | AC18: =IF($I18<200000,INDEX(Home_Data!$C$5:$F$56,V18,1)*(MAX($I18,Home_Data!$B$90)/200000)^Home_Data!$B$89,Y18*(W18/AA18)^(LN(Z18/Y18)/LN(AB18/AA18))) -> 10817.156 | AD18: =IF($K18=100,Home_Data!$B$67,IF($K18=500,Home_Data!$B$69,Home_Data!$B$68)) -> 1 | AE18: =IF($J18<=Home_Data!$B$61,Home_Data!$B$64,IF($J18>=Home_Data!$B$63,Home_Data!$B$66,IF($J18<=Home_Data!$B$62,Home_Data!$B$64+(Home_Data!$B$65-Home_Data!$B$64)*(LN($J18)-LN(Home_Data!$B$61))/(LN(Home_Data!$B$62)-LN(Home_Data!$B$61)),Home_Data!$B$65+(Home_Data!$B$66-Home_Data!$B$65)*(LN($J18)-LN(Home_Data!$B$62))/(LN(Home_Data!$B$63)-LN(Home_Data!$B$62))))) -> 1 | AF18: =IF($E18>=20,Home_Data!$B$80,IF($E18>=10,Home_Data!$B$79,1)) -> 1 | AG18: =IF($D18<1960,Home_Data!$B$81,IF($D18<1980,Home_Data!$B$82,IF($D18>=2000,Home_Data!$B$83,1))) -> 0.95 | AH18: =IF($F18="brick",Home_Data!$B$78,1) -> 1 | AI18: =IF($G18="rental",Home_Data!$B$84,IF($G18="vacation",Home_Data!$B$85,1)) -> 1 | AJ18: =INDEX(Home_Data!$B$70:$B$73,MIN(3,MAX(0,$H18))+1) -> 1 | AK18: =IF(INDEX(Home_Data!$H$5:$H$56,V18)="Yes",1,IF($L18="poor",Home_Data!$B$74,IF($L18="fair",Home_Data!$B$75,IF($L18="excellent",Home_Data!$B$77,Home_Data!$B$76)))) -> 1 | AL18: =IF(($N18=1),Home_Data!$B$86,1)*IF(($O18=1),Home_Data!$B$87,1)*IF(($P18=1),Home_Data!$B$88,1) -> 1.15 | AM18: =AC18*AD18*AE18*AF18*AG18*AH18*AI18*AJ18*AK18*AL18 -> 11817.743 | AN18: =AM18*EXP(-Car_Data!$B$123*Home_Data!$B$91) -> 8607.1379 | AO18: =AM18*EXP(Car_Data!$B$123*Home_Data!$B$91) -> 16225.956 | AP18: =IF($U18>0,IF(AND($U18>=AN18,$U18<=AO18),1,0),"") | AQ18: =IF($U18>0,$U18/AM18-1,"")
A19: TX-1012 | B19: TX | C19: 3150 | D19: 2004 | E19: 10 | F19: frame | G19: own | H19: 0 | I19: 650000 | J19: 1000 | K19: 300 | L19: good | M19: 0 | N19: 0 | O19: 0 | P19: 1 | Q19: 0 | R19: hail or tornado region | V19: =MATCH($B19,Home_Data!$B$5:$B$56,0) -> 43 | W19: =MIN(MAX($I19,50000),3000000) -> 650000 | X19: =IFERROR(MIN(3,MAX(1,MATCH(W19,Home_Data!$C$4:$F$4,1))),1) -> 3 | Y19: =INDEX(Home_Data!$C$5:$F$56,V19,X19) -> 5733 | Z19: =INDEX(Home_Data!$C$5:$F$56,V19,X19+1) -> 7858 | AA19: =INDEX(Home_Data!$C$4:$F$4,X19) -> 400000 | AB19: =INDEX(Home_Data!$C$4:$F$4,X19+1) -> 600000 | AC19: =IF($I19<200000,INDEX(Home_Data!$C$5:$F$56,V19,1)*(MAX($I19,Home_Data!$B$90)/200000)^Home_Data!$B$89,Y19*(W19/AA19)^(LN(Z19/Y19)/LN(AB19/AA19))) -> 8362.6388 | AD19: =IF($K19=100,Home_Data!$B$67,IF($K19=500,Home_Data!$B$69,Home_Data!$B$68)) -> 1 | AE19: =IF($J19<=Home_Data!$B$61,Home_Data!$B$64,IF($J19>=Home_Data!$B$63,Home_Data!$B$66,IF($J19<=Home_Data!$B$62,Home_Data!$B$64+(Home_Data!$B$65-Home_Data!$B$64)*(LN($J19)-LN(Home_Data!$B$61))/(LN(Home_Data!$B$62)-LN(Home_Data!$B$61)),Home_Data!$B$65+(Home_Data!$B$66-Home_Data!$B$65)*(LN($J19)-LN(Home_Data!$B$62))/(LN(Home_Data!$B$63)-LN(Home_Data!$B$62))))) -> 1 | AF19: =IF($E19>=20,Home_Data!$B$80,IF($E19>=10,Home_Data!$B$79,1)) -> 1.1 | AG19: =IF($D19<1960,Home_Data!$B$81,IF($D19<1980,Home_Data!$B$82,IF($D19>=2000,Home_Data!$B$83,1))) -> 0.95 | AH19: =IF($F19="brick",Home_Data!$B$78,1) -> 1 | AI19: =IF($G19="rental",Home_Data!$B$84,IF($G19="vacation",Home_Data!$B$85,1)) -> 1 | AJ19: =INDEX(Home_Data!$B$70:$B$73,MIN(3,MAX(0,$H19))+1) -> 1 | AK19: =IF(INDEX(Home_Data!$H$5:$H$56,V19)="Yes",1,IF($L19="poor",Home_Data!$B$74,IF($L19="fair",Home_Data!$B$75,IF($L19="excellent",Home_Data!$B$77,Home_Data!$B$76)))) -> 1 | AL19: =IF(($N19=1),Home_Data!$B$86,1)*IF(($O19=1),Home_Data!$B$87,1)*IF(($P19=1),Home_Data!$B$88,1) -> 1.08 | AM19: =AC19*AD19*AE19*AF19*AG19*AH19*AI19*AJ19*AK19*AL19 -> 9438.0741 | AN19: =AM19*EXP(-Car_Data!$B$123*Home_Data!$B$91) -> 6873.9697 | AO19: =AM19*EXP(Car_Data!$B$123*Home_Data!$B$91) -> 12958.632 | AP19: =IF($U19>0,IF(AND($U19>=AN19,$U19<=AO19),1,0),"") | AQ19: =IF($U19>0,$U19/AM19-1,"")
... A127: FL-1060 | B127: FL | C127: 1800 | D127: 1984 | E127: 22 | F127: frame | G127: own | H127: 0 | I127: 425000 | J127: 1000 | K127: 300 | L127: excellent | M127: 0 | N127: 0 | O127: 0 | P127: 0 | Q127: 0 | R127: inland, no special hazard | V127: =MATCH($B127,Home_Data!$B$5:$B$56,0) -> 9 | W127: =MIN(MAX($I127,50000),3000000) -> 425000 | X127: =IFERROR(MIN(3,MAX(1,MATCH(W127,Home_Data!$C$4:$F$4,1))),1) -> 3 | Y127: =INDEX(Home_Data!$C$5:$F$56,V127,X127) -> 11161 | Z127: =INDEX(Home_Data!$C$5:$F$56,V127,X127+1) -> 16690 | AA127: =INDEX(Home_Data!$C$4:$F$4,X127) -> 400000 | AB127: =INDEX(Home_Data!$C$4:$F$4,X127+1) -> 600000 | AC127: =IF($I127<200000,INDEX(Home_Data!$C$5:$F$56,V127,1)*(MAX($I127,Home_Data!$B$90)/200000)^Home_Data!$B$89,Y127*(W127/AA127)^(LN(Z127/Y127)/LN(AB127/AA127))) -> 11853.101 | AD127: =IF($K127=100,Home_Data!$B$67,IF($K127=500,Home_Data!$B$69,Home_Data!$B$68)) -> 1 | AE127: =IF($J127<=Home_Data!$B$61,Home_Data!$B$64,IF($J127>=Home_Data!$B$63,Home_Data!$B$66,IF($J127<=Home_Data!$B$62,Home_Data!$B$64+(Home_Data!$B$65-Home_Data!$B$64)*(LN($J127)-LN(Home_Data!$B$61))/(LN(Home_Data!$B$62)-LN(Home_Data!$B$61)),Home_Data!$B$65+(Home_Data!$B$66-Home_Data!$B$65)*(LN($J127)-LN(Home_Data!$B$62))/(LN(Home_Data!$B$63)-LN(Home_Data!$B$62))))) -> 1 | AF127: =IF($E127>=20,Home_Data!$B$80,IF($E127>=10,Home_Data!$B$79,1)) -> 1.3 | AG127: =IF($D127<1960,Home_Data!$B$81,IF($D127<1980,Home_Data!$B$82,IF($D127>=2000,Home_Data!$B$83,1))) -> 1 | AH127: =IF($F127="brick",Home_Data!$B$78,1) -> 1 | AI127: =IF($G127="rental",Home_Data!$B$84,IF($G127="vacation",Home_Data!$B$85,1)) -> 1 | AJ127: =INDEX(Home_Data!$B$70:$B$73,MIN(3,MAX(0,$H127))+1) -> 1 | AK127: =IF(INDEX(Home_Data!$H$5:$H$56,V127)="Yes",1,IF($L127="poor",Home_Data!$B$74,IF($L127="fair",Home_Data!$B$75,IF($L127="excellent",Home_Data!$B$77,Home_Data!$B$76)))) -> 0.89 | AL127: =IF(($N127=1),Home_Data!$B$86,1)*IF(($O127=1),Home_Data!$B$87,1)*IF(($P127=1),Home_Data!$B$88,1) -> 1 | AM127: =AC127*AD127*AE127*AF127*AG127*AH127*AI127*AJ127*AK127*AL127 -> 13714.038 | AN127: =AM127*EXP(-Car_Data!$B$123*Home_Data!$B$91) -> 9988.2539 | AO127: =AM127*EXP(Car_Data!$B$123*Home_Data!$B$91) -> 18829.601 | AP127: =IF($U127>0,IF(AND($U127>=AN127,$U127<=AO127),1,0),"") | AQ127: =IF($U127>0,$U127/AM127-1,"")
A128: CA-1001 | B128: CA | C128: 2400 | D128: 1991 | E128: 0 | F128: brick | G128: own | H128: 0 | I128: 490000 | J128: 1000 | K128: 300 | M128: 0 | N128: 0 | O128: 1 | P128: 0 | Q128: 1 | R128: wildfire-exposed area; earthquake region | V128: =MATCH($B128,Home_Data!$B$5:$B$56,0) -> 5 | W128: =MIN(MAX($I128,50000),3000000) -> 490000 | X128: =IFERROR(MIN(3,MAX(1,MATCH(W128,Home_Data!$C$4:$F$4,1))),1) -> 3 | Y128: =INDEX(Home_Data!$C$5:$F$56,V128,X128) -> 2090 | Z128: =INDEX(Home_Data!$C$5:$F$56,V128,X128+1) -> 3092 | AA128: =INDEX(Home_Data!$C$4:$F$4,X128) -> 400000 | AB128: =INDEX(Home_Data!$C$4:$F$4,X128+1) -> 600000 | AC128: =IF($I128<200000,INDEX(Home_Data!$C$5:$F$56,V128,1)*(MAX($I128,Home_Data!$B$90)/200000)^Home_Data!$B$89,Y128*(W128/AA128)^(LN(Z128/Y128)/LN(AB128/AA128))) -> 2542.613 | AD128: =IF($K128=100,Home_Data!$B$67,IF($K128=500,Home_Data!$B$69,Home_Data!$B$68)) -> 1 | AE128: =IF($J128<=Home_Data!$B$61,Home_Data!$B$64,IF($J128>=Home_Data!$B$63,Home_Data!$B$66,IF($J128<=Home_Data!$B$62,Home_Data!$B$64+(Home_Data!$B$65-Home_Data!$B$64)*(LN($J128)-LN(Home_Data!$B$61))/(LN(Home_Data!$B$62)-LN(Home_Data!$B$61)),Home_Data!$B$65+(Home_Data!$B$66-Home_Data!$B$65)*(LN($J128)-LN(Home_Data!$B$62))/(LN(Home_Data!$B$63)-LN(Home_Data!$B$62))))) -> 1 | AF128: =IF($E128>=20,Home_Data!$B$80,IF($E128>=10,Home_Data!$B$79,1)) -> 1 | AG128: =IF($D128<1960,Home_Data!$B$81,IF($D128<1980,Home_Data!$B$82,IF($D128>=2000,Home_Data!$B$83,1))) -> 1 | AH128: =IF($F128="brick",Home_Data!$B$78,1) -> 0.98 | AI128: =IF($G128="rental",Home_Data!$B$84,IF($G128="vacation",Home_Data!$B$85,1)) -> 1 | AJ128: =INDEX(Home_Data!$B$70:$B$73,MIN(3,MAX(0,$H128))+1) -> 1 | AK128: =IF(INDEX(Home_Data!$H$5:$H$56,V128)="Yes",1,IF($L128="poor",Home_Data!$B$74,IF($L128="fair",Home_Data!$B$75,IF($L128="excellent",Home_Data!$B$77,Home_Data!$B$76)))) -> 1 | AL128: =IF(($N128=1),Home_Data!$B$86,1)*IF(($O128=1),Home_Data!$B$87,1)*IF(($P128=1),Home_Data!$B$88,1) -> 1.15 | AM128: =AC128*AD128*AE128*AF128*AG128*AH128*AI128*AJ128*AK128*AL128 -> 2865.5249 | AN128: =AM128*EXP(-Car_Data!$B$123*Home_Data!$B$91) -> 2087.0286 | AO128: =AM128*EXP(Car_Data!$B$123*Home_Data!$B$91) -> 3934.4131 | AP128: =IF($U128>0,IF(AND($U128>=AN128,$U128<=AO128),1,0),"") | AQ128: =IF($U128>0,$U128/AM128-1,"")
A129: CA-1002 | B129: CA | C129: 3400 | D129: 1969 | E129: 19 | F129: frame | G129: own | H129: 0 | I129: 845000 | J129: 1000 | K129: 300 | M129: 0 | N129: 0 | O129: 1 | P129: 0 | Q129: 1 | R129: wildfire-exposed area; earthquake region | V129: =MATCH($B129,Home_Data!$B$5:$B$56,0) -> 5 | W129: =MIN(MAX($I129,50000),3000000) -> 845000 | X129: =IFERROR(MIN(3,MAX(1,MATCH(W129,Home_Data!$C$4:$F$4,1))),1) -> 3 | Y129: =INDEX(Home_Data!$C$5:$F$56,V129,X129) -> 2090 | Z129: =INDEX(Home_Data!$C$5:$F$56,V129,X129+1) -> 3092 | AA129: =INDEX(Home_Data!$C$4:$F$4,X129) -> 400000 | AB129: =INDEX(Home_Data!$C$4:$F$4,X129+1) -> 600000 | AC129: =IF($I129<200000,INDEX(Home_Data!$C$5:$F$56,V129,1)*(MAX($I129,Home_Data!$B$90)/200000)^Home_Data!$B$89,Y129*(W129/AA129)^(LN(Z129/Y129)/LN(AB129/AA129))) -> 4304.0738 | AD129: =IF($K129=100,Home_Data!$B$67,IF($K129=500,Home_Data!$B$69,Home_Data!$B$68)) -> 1 | AE129: =IF($J129<=Home_Data!$B$61,Home_Data!$B$64,IF($J129>=Home_Data!$B$63,Home_Data!$B$66,IF($J129<=Home_Data!$B$62,Home_Data!$B$64+(Home_Data!$B$65-Home_Data!$B$64)*(LN($J129)-LN(Home_Data!$B$61))/(LN(Home_Data!$B$62)-LN(Home_Data!$B$61)),Home_Data!$B$65+(Home_Data!$B$66-Home_Data!$B$65)*(LN($J129)-LN(Home_Data!$B$62))/(LN(Home_Data!$B$63)-LN(Home_Data!$B$62))))) -> 1 | AF129: =IF($E129>=20,Home_Data!$B$80,IF($E129>=10,Home_Data!$B$79,1)) -> 1.1 | AG129: =IF($D129<1960,Home_Data!$B$81,IF($D129<1980,Home_Data!$B$82,IF($D129>=2000,Home_Data!$B$83,1))) -> 1.08 | AH129: =IF($F129="brick",Home_Data!$B$78,1) -> 1 | AI129: =IF($G129="rental",Home_Data!$B$84,IF($G129="vacation",Home_Data!$B$85,1)) -> 1 | AJ129: =INDEX(Home_Data!$B$70:$B$73,MIN(3,MAX(0,$H129))+1) -> 1 | AK129: =IF(INDEX(Home_Data!$H$5:$H$56,V129)="Yes",1,IF($L129="poor",Home_Data!$B$74,IF($L129="fair",Home_Data!$B$75,IF($L129="excellent",Home_Data!$B$77,Home_Data!$B$76)))) -> 1 | AL129: =IF(($N129=1),Home_Data!$B$86,1)*IF(($O129=1),Home_Data!$B$87,1)*IF(($P129=1),Home_Data!$B$88,1) -> 1.15 | AM129: =AC129*AD129*AE129*AF129*AG129*AH129*AI129*AJ129*AK129*AL129 -> 5880.2256 | AN129: =AM129*EXP(-Car_Data!$B$123*Home_Data!$B$91) -> 4282.7055 | AO129: =AM129*EXP(Car_Data!$B$123*Home_Data!$B$91) -> 8073.647 | AP129: =IF($U129>0,IF(AND($U129>=AN129,$U129<=AO129),1,0),"") | AQ129: =IF($U129>0,$U129/AM129-1,"")
A130: CA-1003 | B130: CA | C130: 1300 | D130: 2018 | E130: 1 | F130: frame | G130: own | H130: 0 | I130: 270000 | J130: 1000 | K130: 500 | M130: 0 | N130: 0 | O130: 1 | P130: 0 | Q130: 1 | R130: wildfire-exposed area; earthquake region | V130: =MATCH($B130,Home_Data!$B$5:$B$56,0) -> 5 | W130: =MIN(MAX($I130,50000),3000000) -> 270000 | X130: =IFERROR(MIN(3,MAX(1,MATCH(W130,Home_Data!$C$4:$F$4,1))),1) -> 1 | Y130: =INDEX(Home_Data!$C$5:$F$56,V130,X130) -> 1244 | Z130: =INDEX(Home_Data!$C$5:$F$56,V130,X130+1) -> 1653 | AA130: =INDEX(Home_Data!$C$4:$F$4,X130) -> 200000 | AB130: =INDEX(Home_Data!$C$4:$F$4,X130+1) -> 300000 | AC130: =IF($I130<200000,INDEX(Home_Data!$C$5:$F$56,V130,1)*(MAX($I130,Home_Data!$B$90)/200000)^Home_Data!$B$89,Y130*(W130/AA130)^(LN(Z130/Y130)/LN(AB130/AA130))) -> 1535.3013 | AD130: =IF($K130=100,Home_Data!$B$67,IF($K130=500,Home_Data!$B$69,Home_Data!$B$68)) -> 1.005 | AE130: =IF($J130<=Home_Data!$B$61,Home_Data!$B$64,IF($J130>=Home_Data!$B$63,Home_Data!$B$66,IF($J130<=Home_Data!$B$62,Home_Data!$B$64+(Home_Data!$B$65-Home_Data!$B$64)*(LN($J130)-LN(Home_Data!$B$61))/(LN(Home_Data!$B$62)-LN(Home_Data!$B$61)),Home_Data!$B$65+(Home_Data!$B$66-Home_Data!$B$65)*(LN($J130)-LN(Home_Data!$B$62))/(LN(Home_Data!$B$63)-LN(Home_Data!$B$62))))) -> 1 | AF130: =IF($E130>=20,Home_Data!$B$80,IF($E130>=10,Home_Data!$B$79,1)) -> 1 | AG130: =IF($D130<1960,Home_Data!$B$81,IF($D130<1980,Home_Data!$B$82,IF($D130>=2000,Home_Data!$B$83,1))) -> 0.95 | AH130: =IF($F130="brick",Home_Data!$B$78,1) -> 1 | AI130: =IF($G130="rental",Home_Data!$B$84,IF($G130="vacation",Home_Data!$B$85,1)) -> 1 | AJ130: =INDEX(Home_Data!$B$70:$B$73,MIN(3,MAX(0,$H130))+1) -> 1 | AK130: =IF(INDEX(Home_Data!$H$5:$H$56,V130)="Yes",1,IF($L130="poor",Home_Data!$B$74,IF($L130="fair",Home_Data!$B$75,IF($L130="excellent",Home_Data!$B$77,Home_Data!$B$76)))) -> 1 | AL130: =IF(($N130=1),Home_Data!$B$86,1)*IF(($O130=1),Home_Data!$B$87,1)*IF(($P130=1),Home_Data!$B$88,1) -> 1.15 | AM130: =AC130*AD130*AE130*AF130*AG130*AH130*AI130*AJ130*AK130*AL130 -> 1685.7032 | AN130: =AM130*EXP(-Car_Data!$B$123*Home_Data!$B$91) -> 1227.737 | AO130: =AM130*EXP(Car_Data!$B$123*Home_Data!$B$91) -> 2314.4984 | AP130: =IF($U130>0,IF(AND($U130>=AN130,$U130<=AO130),1,0),"") | AQ130: =IF($U130>0,$U130/AM130-1,"")
A131: CA-1004 | B131: CA | C131: 2950 | D131: 1971 | E131: 20 | F131: frame | G131: own | H131: 0 | I131: 850000 | J131: 2500 | K131: 100 | M131: 0 | N131: 0 | O131: 0 | P131: 0 | Q131: 0 | R131: inland, no special hazard | V131: =MATCH($B131,Home_Data!$B$5:$B$56,0) -> 5 | W131: =MIN(MAX($I131,50000),3000000) -> 850000 | X131: =IFERROR(MIN(3,MAX(1,MATCH(W131,Home_Data!$C$4:$F$4,1))),1) -> 3 | Y131: =INDEX(Home_Data!$C$5:$F$56,V131,X131) -> 2090 | Z131: =INDEX(Home_Data!$C$5:$F$56,V131,X131+1) -> 3092 | AA131: =INDEX(Home_Data!$C$4:$F$4,X131) -> 400000 | AB131: =INDEX(Home_Data!$C$4:$F$4,X131+1) -> 600000 | AC131: =IF($I131<200000,INDEX(Home_Data!$C$5:$F$56,V131,1)*(MAX($I131,Home_Data!$B$90)/200000)^Home_Data!$B$89,Y131*(W131/AA131)^(LN(Z131/Y131)/LN(AB131/AA131))) -> 4328.6717 | AD131: =IF($K131=100,Home_Data!$B$67,IF($K131=500,Home_Data!$B$69,Home_Data!$B$68)) -> 0.991 | AE131: =IF($J131<=Home_Data!$B$61,Home_Data!$B$64,IF($J131>=Home_Data!$B$63,Home_Data!$B$66,IF($J131<=Home_Data!$B$62,Home_Data!$B$64+(Home_Data!$B$65-Home_Data!$B$64)*(LN($J131)-LN(Home_Data!$B$61))/(LN(Home_Data!$B$62)-LN(Home_Data!$B$61)),Home_Data!$B$65+(Home_Data!$B$66-Home_Data!$B$65)*(LN($J131)-LN(Home_Data!$B$62))/(LN(Home_Data!$B$63)-LN(Home_Data!$B$62))))) -> 0.91 | AF131: =IF($E131>=20,Home_Data!$B$80,IF($E131>=10,Home_Data!$B$79,1)) -> 1.3 | AG131: =IF($D131<1960,Home_Data!$B$81,IF($D131<1980,Home_Data!$B$82,IF($D131>=2000,Home_Data!$B$83,1))) -> 1.08 | AH131: =IF($F131="brick",Home_Data!$B$78,1) -> 1 | AI131: =IF($G131="rental",Home_Data!$B$84,IF($G131="vacation",Home_Data!$B$85,1)) -> 1 | AJ131: =INDEX(Home_Data!$B$70:$B$73,MIN(3,MAX(0,$H131))+1) -> 1 | AK131: =IF(INDEX(Home_Data!$H$5:$H$56,V131)="Yes",1,IF($L131="poor",Home_Data!$B$74,IF($L131="fair",Home_Data!$B$75,IF($L131="excellent",Home_Data!$B$77,Home_Data!$B$76)))) -> 1 | AL131: =IF(($N131=1),Home_Data!$B$86,1)*IF(($O131=1),Home_Data!$B$87,1)*IF(($P131=1),Home_Data!$B$88,1) -> 1 | AM131: =AC131*AD131*AE131*AF131*AG131*AH131*AI131*AJ131*AK131*AL131 -> 5480.7097 | AN131: =AM131*EXP(-Car_Data!$B$123*Home_Data!$B$91) -> 3991.7288 | AO131: =AM131*EXP(Car_Data!$B$123*Home_Data!$B$91) -> 7525.1052 | AP131: =IF($U131>0,IF(AND($U131>=AN131,$U131<=AO131),1,0),"") | AQ131: =IF($U131>0,$U131/AM131-1,"")
A132: CA-1005 | B132: CA | C132: 1550 | D132: 2005 | E132: 5 | F132: frame | G132: own | H132: 0 | I132: 395000 | J132: 1000 | K132: 300 | M132: 0 | N132: 0 | O132: 0 | P132: 0 | Q132: 1 | R132: earthquake region | V132: =MATCH($B132,Home_Data!$B$5:$B$56,0) -> 5 | W132: =MIN(MAX($I132,50000),3000000) -> 395000 | X132: =IFERROR(MIN(3,MAX(1,MATCH(W132,Home_Data!$C$4:$F$4,1))),1) -> 2 | Y132: =INDEX(Home_Data!$C$5:$F$56,V132,X132) -> 1653 | Z132: =INDEX(Home_Data!$C$5:$F$56,V132,X132+1) -> 2090 | AA132: =INDEX(Home_Data!$C$4:$F$4,X132) -> 300000 | AB132: =INDEX(Home_Data!$C$4:$F$4,X132+1) -> 400000 | AC132: =IF($I132<200000,INDEX(Home_Data!$C$5:$F$56,V132,1)*(MAX($I132,Home_Data!$B$90)/200000)^Home_Data!$B$89,Y132*(W132/AA132)^(LN(Z132/Y132)/LN(AB132/AA132))) -> 2068.6733 | AD132: =IF($K132=100,Home_Data!$B$67,IF($K132=500,Home_Data!$B$69,Home_Data!$B$68)) -> 1 | AE132: =IF($J132<=Home_Data!$B$61,Home_Data!$B$64,IF($J132>=Home_Data!$B$63,Home_Data!$B$66,IF($J132<=Home_Data!$B$62,Home_Data!$B$64+(Home_Data!$B$65-Home_Data!$B$64)*(LN($J132)-LN(Home_Data!$B$61))/(LN(Home_Data!$B$62)-LN(Home_Data!$B$61)),Home_Data!$B$65+(Home_Data!$B$66-Home_Data!$B$65)*(LN($J132)-LN(Home_Data!$B$62))/(LN(Home_Data!$B$63)-LN(Home_Data!$B$62))))) -> 1 | AF132: =IF($E132>=20,Home_Data!$B$80,IF($E132>=10,Home_Data!$B$79,1)) -> 1 | AG132: =IF($D132<1960,Home_Data!$B$81,IF($D132<1980,Home_Data!$B$82,IF($D132>=2000,Home_Data!$B$83,1))) -> 0.95 | AH132: =IF($F132="brick",Home_Data!$B$78,1) -> 1 | AI132: =IF($G132="rental",Home_Data!$B$84,IF($G132="vacation",Home_Data!$B$85,1)) -> 1 | AJ132: =INDEX(Home_Data!$B$70:$B$73,MIN(3,MAX(0,$H132))+1) -> 1 | AK132: =IF(INDEX(Home_Data!$H$5:$H$56,V132)="Yes",1,IF($L132="poor",Home_Data!$B$74,IF($L132="fair",Home_Data!$B$75,IF($L132="excellent",Home_Data!$B$77,Home_Data!$B$76)))) -> 1 | AL132: =IF(($N132=1),Home_Data!$B$86,1)*IF(($O132=1),Home_Data!$B$87,1)*IF(($P132=1),Home_Data!$B$88,1) -> 1 | AM132: =AC132*AD132*AE132*AF132*AG132*AH132*AI132*AJ132*AK132*AL132 -> 1965.2396 | AN132: =AM132*EXP(-Car_Data!$B$123*Home_Data!$B$91) -> 1431.3299 | AO132: =AM132*EXP(Car_Data!$B$123*Home_Data!$B$91) -> 2698.3066 | AP132: =IF($U132>0,IF(AND($U132>=AN132,$U132<=AO132),1,0),"") | AQ132: =IF($U132>0,$U132/AM132-1,"")
A133: CA-1006 | B133: CA | C133: 3600 | D133: 1974 | E133: 5 | F133: frame | G133: own | H133: 0 | I133: 930000 | J133: 5000 | K133: 300 | M133: 0 | N133: 0 | O133: 0 | P133: 0 | Q133: 1 | R133: earthquake region | V133: =MATCH($B133,Home_Data!$B$5:$B$56,0) -> 5 | W133: =MIN(MAX($I133,50000),3000000) -> 930000 | X133: =IFERROR(MIN(3,MAX(1,MATCH(W133,Home_Data!$C$4:$F$4,1))),1) -> 3 | Y133: =INDEX(Home_Data!$C$5:$F$56,V133,X133) -> 2090 | Z133: =INDEX(Home_Data!$C$5:$F$56,V133,X133+1) -> 3092 | AA133: =INDEX(Home_Data!$C$4:$F$4,X133) -> 400000 | AB133: =INDEX(Home_Data!$C$4:$F$4,X133+1) -> 600000 | AC133: =IF($I133<200000,INDEX(Home_Data!$C$5:$F$56,V133,1)*(MAX($I133,Home_Data!$B$90)/200000)^Home_Data!$B$89,Y133*(W133/AA133)^(LN(Z133/Y133)/LN(AB133/AA133))) -> 4721.5877 | AD133: =IF($K133=100,Home_Data!$B$67,IF($K133=500,Home_Data!$B$69,Home_Data!$B$68)) -> 1 | AE133: =IF($J133<=Home_Data!$B$61,Home_Data!$B$64,IF($J133>=Home_Data!$B$63,Home_Data!$B$66,IF($J133<=Home_Data!$B$62,Home_Data!$B$64+(Home_Data!$B$65-Home_Data!$B$64)*(LN($J133)-LN(Home_Data!$B$61))/(LN(Home_Data!$B$62)-LN(Home_Data!$B$61)),Home_Data!$B$65+(Home_Data!$B$66-Home_Data!$B$65)*(LN($J133)-LN(Home_Data!$B$62))/(LN(Home_Data!$B$63)-LN(Home_Data!$B$62))))) -> 0.84 | AF133: =IF($E133>=20,Home_Data!$B$80,IF($E133>=10,Home_Data!$B$79,1)) -> 1 | AG133: =IF($D133<1960,Home_Data!$B$81,IF($D133<1980,Home_Data!$B$82,IF($D133>=2000,Home_Data!$B$83,1))) -> 1.08 | AH133: =IF($F133="brick",Home_Data!$B$78,1) -> 1 | AI133: =IF($G133="rental",Home_Data!$B$84,IF($G133="vacation",Home_Data!$B$85,1)) -> 1 | AJ133: =INDEX(Home_Data!$B$70:$B$73,MIN(3,MAX(0,$H133))+1) -> 1 | AK133: =IF(INDEX(Home_Data!$H$5:$H$56,V133)="Yes",1,IF($L133="poor",Home_Data!$B$74,IF($L133="fair",Home_Data!$B$75,IF($L133="excellent",Home_Data!$B$77,Home_Data!$B$76)))) -> 1 | AL133: =IF(($N133=1),Home_Data!$B$86,1)*IF(($O133=1),Home_Data!$B$87,1)*IF(($P133=1),Home_Data!$B$88,1) -> 1 | AM133: =AC133*AD133*AE133*AF133*AG133*AH133*AI133*AJ133*AK133*AL133 -> 4283.4244 | AN133: =AM133*EXP(-Car_Data!$B$123*Home_Data!$B$91) -> 3119.7179 | AO133: =AM133*EXP(Car_Data!$B$123*Home_Data!$B$91) -> 5881.2126 | AP133: =IF($U133>0,IF(AND($U133>=AN133,$U133<=AO133),1,0),"") | AQ133: =IF($U133>0,$U133/AM133-1,"")
